<?xml version="1.0" ?>
<!-- Generated using onshape-to-robot -->
<!-- Onshape https://cad.onshape.com/documents/7715cc284bb430fe6dab4ffd/w/4fd0791b683777b02f8d975a/e/826c553ede3b7592eb9ca800 -->
<mujoco model="so101_new_calib">
  <compiler angle="radian" meshdir="assets" autolimits="true"/>
  <default>
    <default class="so101_new_calib">
      <joint damping="1" frictionloss="0.1" armature="0.005"/>
      <position kp="50"/>
      <default class="visual">
        <geom type="mesh" contype="0" conaffinity="0" group="2"/>
      </default>
<!-- 默认碰撞设置 -->
      <default class="collision">
        <geom group="3"/>
<!-- 从100来的finger摩擦和阻尼设置 -->
        <default class="finger_collision">
          <geom type="box" solimp="2 1 0.01" solref="0.01 1" friction="1 0.005 0.0001"/>
        </default>

      </default>
    </default>
<!-- Additional joints_properties.xml -->
    <default class="sts3215">
      <geom contype="0" conaffinity="0"/>
      <joint damping="0.60" frictionloss="0.052" armature="0.028"/>
      <!-- For lerobot this are not exactly the motor params as the Kp and Kd not map 1-to-1 thus motor idendification with lerobot Kp=16 and Kd=32 should actually be done -->
      <position kp="17.8"/>
    </default>
    <default class="backlash">
      <!-- +/- 0.5° of backlash -->
      <joint damping="0.01" frictionloss="0" armature="0.01" limited="true" range="-0.008726646259971648 0.008726646259971648"/>
    </default>
  </default>
  <!-- <default>
  </default> -->
  <worldbody>
    


    <!-- 你的机械臂 body 结构 ... -->
    <!-- <body name="base" pos="0 0 0.402" quat="1 0 0 0" childclass="so101_new_calib"> -->
    <body name="base" pos="0 0 0.402" quat="1 0 0 0" childclass="so101_new_calib">

      <!-- 顶部相机，相对基座固定,fovy默认45 -->
      <!-- <camera name="top_cam" mode="fixed" pos="0.2 0 0.5" xyaxes="0 -1 0 1 0 0" fovy="60"/> -->
      <camera name="old_front" mode="fixed" pos="0.5 0 0.5" xyaxes="0 1 0 -0.9397 0 0.3420" fovy="55"/>
      <!-- 侧面相机，相对基座固定,fovy默认45 -->
      <camera name="side_high" mode="fixed" pos="0.18 -0.5 0.4" xyaxes="1 0 0 0 0.5 0.866" fovy="60"/>
      <camera name="side" mode="fixed" pos="0.18 -0.55 0.3" xyaxes="1 0 0 0 0.3420 0.9397" fovy="70"/>


      <!-- <camera name="front" mode="fixed" pos="0.5 -0.4 0.4" xyaxes="0.826590 0.562805 0.000000 -0.374761 0.550411 0.746057"/> -->
      <camera name="front" mode="fixed" pos="0.5 -0.4 0.38" xyaxes="0.826590 0.562805 0.2 -0.374761 0.550411 0.746057" fovy="40"/>

      <inertial pos="0.0137179 -5.19711e-05 0.0334843" mass="0.147" fullinertia="0.000114686 0.000136117 0.000130364 -4.59787e-07 4.97151e-06 9.75275e-08"/>
      <!-- Part base_motor_holder_so101_v1 -->
      <geom type="mesh" class="visual" pos="-0.00636471 -9.94414e-05 -0.0024" quat="0.5 0.5 0.5 0.5" mesh="base_motor_holder_so101_v1" material="arm_color"/>
      <!-- <geom type="mesh" class="collision" pos="-0.00636471 -9.94414e-05 -0.0024" quat="0.5 0.5 0.5 0.5" mesh="base_motor_holder_so101_v1" material="arm_color"/> -->
      <!-- Part base_so101_v2 -->
      <geom type="mesh" class="visual" pos="-0.00636471 -8.97657e-09 -0.0024" quat="0.5 0.5 0.5 0.5" mesh="base_so101_v2" material="arm_color"/>
      <geom type="mesh" class="collision" pos="-0.04 0 -0.01" quat="0.5 0.5 0.5 0.5" mesh="base_so101_v2" material="arm_color"/>
      <!-- Part sts3215_03a_v1 -->
      <geom type="mesh" class="visual" pos="0.0263353 -8.97657e-09 0.0437" quat="1 -2.85511e-16 -9.64433e-17 6.12908e-16" mesh="sts3215_03a_v1" material="motor_color"/>
      <!-- Part waveshare_mounting_plate_so101_v2 -->
      <geom type="mesh" class="visual" pos="-0.0309827 -0.000199441 0.0474" quat="0.5 0.5 0.5 0.5" mesh="waveshare_mounting_plate_so101_v2" material="arm_color"/>
      <!-- Frame baseframe -->
      <site group="3" name="baseframe" pos="8.67362e-19 9.55596e-18 3.46945e-18" quat="1 -8.17396e-19 3.78392e-17 2.22045e-16"/>
      <!-- Link shoulder -->
      <body name="shoulder" pos="0.0388353 -8.97657e-09 0.0624" quat="3.56167e-16 1.22818e-15 -1 -4.14635e-16">
        <!-- Joint from base to shoulder -->
        <joint axis="0 0 1" name="shoulder_pan" type="hinge" range="-1.9198621771937616 1.9198621771937634" class="sts3215"/>
        <inertial pos="-0.0307604 -1.66727e-05 -0.0252713" mass="0.100006" fullinertia="8.3759e-05 8.10403e-05 2.39783e-05 7.55525e-08 -1.16342e-06 1.54663e-07"/>
        <!-- Part sts3215_03a_v1_2 -->
        <geom type="mesh" class="visual" pos="-0.0303992 0.000422241 -0.0417" quat="0.5 0.5 0.5 -0.5" mesh="sts3215_03a_v1" material="motor_color"/>
        <geom type="mesh" class="collision" pos="-0.0303992 0.000422241 -0.0417" quat="0.5 0.5 0.5 -0.5" mesh="sts3215_03a_v1" material="motor_color"/>
        <!-- Part motor_holder_so101_base_v1 -->
        <geom type="mesh" class="visual" pos="-0.0675992 -0.000177759 0.0158499" quat="0.5 0.5 -0.5 0.5" mesh="motor_holder_so101_base_v1" material="arm_color"/>
        <geom type="mesh" class="collision" pos="-0.0675992 -0.000177759 0.0158499" quat="0.5 0.5 -0.5 0.5" mesh="motor_holder_so101_base_v1" material="arm_color"/>
        <!-- Part rotation_pitch_so101_v1 -->
        <geom type="mesh" class="visual" pos="0.0122008 2.22413e-05 0.0464" quat="0.707107 -0.707107 -0 8.3163e-34" mesh="rotation_pitch_so101_v1" material="arm_color"/>
        <geom type="mesh" class="collision" pos="0.0122008 2.22413e-05 0.0464" quat="0.707107 -0.707107 -0 8.3163e-34" mesh="rotation_pitch_so101_v1" material="arm_color"/>
        <!-- Link upper_arm -->
        <body name="upper_arm" pos="-0.0303992 -0.0182778 -0.0542" quat="0.5 -0.5 -0.5 -0.5">
          <!-- Joint from shoulder to upper_arm -->
          <joint axis="0 0 1" name="shoulder_lift" type="hinge" range="-1.7453292519943224 1.7453292519943366" class="sts3215"/>
          <inertial pos="-0.0898471 -0.00838224 0.0184089" mass="0.103" fullinertia="4.08002e-05 0.000147318 0.000142487 -1.97819e-05 -4.03016e-08 8.97326e-09"/>
          <!-- Part sts3215_03a_v1_3 -->
          <geom type="mesh" class="visual" pos="-0.11257 -0.0155 0.0187" quat="4.56308e-16 -0.707107 0.707107 -1.37383e-16" mesh="sts3215_03a_v1" material="motor_color"/>
          <geom type="mesh" class="collision" pos="-0.11257 -0.0155 0.0187" quat="4.56308e-16 -0.707107 0.707107 -1.37383e-16" mesh="sts3215_03a_v1" material="motor_color"/>
          <!-- Part upper_arm_so101_v1 -->
          <geom type="mesh" class="visual" pos="-0.065085 0.012 0.0182" quat="0 1 0 0" mesh="upper_arm_so101_v1" material="arm_color"/>
          <geom type="mesh" class="collision" pos="-0.065085 0.012 0.0182" quat="0 1 0 0" mesh="upper_arm_so101_v1" material="arm_color"/>
          <!-- Link lower_arm -->
          <body name="lower_arm" pos="-0.11257 -0.028 1.73763e-16" quat="0.707107 -5.98613e-17 -2.58051e-17 0.707107">
            <!-- Joint from upper_arm to lower_arm -->
            <!-- Note: 5-degree calibration offset applied to joint range -->
            <joint axis="0 0 1" name="elbow_flex" type="hinge" range="-1.69 1.69" class="sts3215"/>
            <inertial pos="-0.0980701 0.00324376 0.0182831" mass="0.104" fullinertia="2.87438e-05 0.000159844 0.00014529 7.41152e-06 1.26409e-06 -4.90188e-08"/>
            <!-- Part under_arm_so101_v1 -->
            <geom type="mesh" class="visual" pos="-0.0648499 -0.032 0.0182" quat="0 1 0 0" mesh="under_arm_so101_v1" material="arm_color"/>
            <geom type="mesh" class="collision" pos="-0.0648499 -0.032 0.0182" quat="0 1 0 0" mesh="under_arm_so101_v1" material="arm_color"/>
            <!-- Part motor_holder_so101_wrist_v1 -->
            <geom type="mesh" class="visual" pos="-0.0648499 -0.032 0.018" quat="3.92687e-16 -1 -1.9186e-15 -6.38378e-16" mesh="motor_holder_so101_wrist_v1" material="arm_color"/>
            <geom type="mesh" class="collision" pos="-0.0648499 -0.032 0.018" quat="3.92687e-16 -1 -1.9186e-15 -6.38378e-16" mesh="motor_holder_so101_wrist_v1" material="arm_color"/>
            <!-- Part sts3215_03a_v1_4 -->
            <geom type="mesh" class="visual" pos="-0.1224 0.0052 0.0187" quat="7.21645e-16 1.56949e-15 1 -3.33067e-16" mesh="sts3215_03a_v1" material="motor_color"/>
            <geom type="mesh" class="collision" pos="-0.1224 0.0052 0.0187" quat="7.21645e-16 1.56949e-15 1 -3.33067e-16" mesh="sts3215_03a_v1" material="motor_color"/>
            <!-- Link wrist -->
            <body name="wrist" pos="-0.1349 0.0052 3.62355e-17" quat="0.707107 9.58722e-16 -7.51313e-16 -0.707107">
              <!-- Joint from lower_arm to wrist -->
              <joint axis="0 0 1" name="wrist_flex" type="hinge" range="-1.6580628494556928 1.6580627293335335" class="sts3215"/>
              <inertial pos="-0.000103312 -0.0386143 0.0281156" mass="0.079" fullinertia="3.68263e-05 2.5391e-05 2.1e-05 1.7893e-08 -5.28128e-08 3.6412e-06"/>
              <!-- Part sts3215_03a_no_horn_v1 -->
              <geom type="mesh" class="visual" pos="8.32667e-17 -0.0424 0.0306" quat="0.5 0.5 0.5 -0.5" mesh="sts3215_03a_no_horn_v1" material="motor_color"/>
              <geom type="mesh" class="collision" pos="8.32667e-17 -0.0424 0.0306" quat="0.5 0.5 0.5 -0.5" mesh="sts3215_03a_no_horn_v1" material="motor_color"/>
              <!-- Part wrist_roll_pitch_so101_v2 -->
              <geom type="mesh" class="visual" pos="0 -0.028 0.0181" quat="0.5 -0.5 -0.5 -0.5" mesh="wrist_roll_pitch_so101_v2" material="arm_color"/>
              <geom type="mesh" class="collision" pos="0 -0.028 0.0181" quat="0.5 -0.5 -0.5 -0.5" mesh="wrist_roll_pitch_so101_v2" material="arm_color"/>
              <!-- Link gripper -->
              <body name="gripper" pos="5.55112e-17 -0.0611 0.0181" quat="0.0172091 -0.0172091 0.706897 0.706897">
                <!-- Joint from wrist to gripper -->
                <joint axis="0 0 1" name="wrist_roll" type="hinge" range="-2.7438472969992493 2.841206309382605" class="sts3215"/>
                <inertial pos="0.000213627 0.000245138 -0.025187" mass="0.087" fullinertia="2.75087e-05 4.33657e-05 3.45059e-05 -3.35241e-07 -5.7352e-06 -5.17847e-08"/>
                <!-- Part sts3215_03a_v1_5 -->
                <geom type="mesh" class="visual" pos="0.0077 0.0001 -0.0234" quat="0.707107 -0.707107 1.66015e-15 6.45094e-15" mesh="sts3215_03a_v1" material="motor_color"/>
                <geom type="mesh" class="collision" pos="0.0077 0.0001 -0.0234" quat="0.707107 -0.707107 1.66015e-15 6.45094e-15" mesh="sts3215_03a_v1" material="motor_color"/>

                <!-- Part 固定夹爪: wrist_roll_follower_so101_v1 -->
                <geom type="mesh" class="visual" pos="8.32667e-17 -0.000218214 0.000949706" quat="0 1 0 0" mesh="wrist_roll_follower_so101_v1" material="arm_color"/>

                <!-- front 相机在固定夹爪上安装 -->
                <!-- fovy：视场角（类似焦距，单位为度，越小越“长焦”）  -->
                <camera name="wrist" mode="fixed" pos="0.0 0.09 0.015" xyaxes="1 0 0 0 0.866 -0.5" fovy="42"/>
                
          <!-- 这里 -->
          <!-- 用的是100的简化collision模型*2 -->
                <geom type="mesh" class="collision" pos="8.32667e-17 -0.000218214 0.000949706" quat="0 0 1 1" mesh="From100_Fixed_Jaw_Collision_1"/>
                <geom type="mesh" class="collision" pos="8.32667e-17 -0.000218214 0.000949706" quat="0 0 1 1" mesh="From100_Fixed_Jaw_Collision_2"/>
          <!-- 手工肉垫 -->
                <geom class="finger_collision" name="fixed_jaw_pad_1" size="0.0011 0.004 0.005" pos="-0.009 -0.00 -0.0995" rgba="1 0 0 0.5"/>
                <geom class="finger_collision" name="fixed_jaw_pad_2" size="0.0015 0.006 0.005" pos="-0.011 -0.00 -0.0895" rgba="1 0 0 0.5"/>
                <geom class="finger_collision" name="fixed_jaw_pad_3" size="0.0018 0.007 0.01" pos="-0.013 -0.00 -0.0745" rgba="1 0 0 0.5"/>
                <geom class="finger_collision" name="fixed_jaw_pad_4" size="0.0018 0.008 0.01" pos="-0.015 -0.00 -0.055" rgba="1 0 0 0.5"/>
                
                <!-- <geom name="gripper_left_collision" friction="1 0.005 0.0001" class="finger_collision" type="box" pos="-0.015 -0.00 -0.055" size="0.005 0.01 0.05" condim="4" contype="1" conaffinity="1" rgba="0 1 0 0.8"/> -->
                <!-- collision 使用新的 mesh -->
                <!-- <geom type="mesh" class="collision" pos="8.32667e-17 -0.000218214 0.000949706" quat="0 0 1 1" mesh="From100_Fixed_Jaw_Collision"/> -->
                <!-- <geom type="mesh" scale="0.9 0.9 0.9" friction="1 0.005 0.0001" class="collision" pos="8.32667e-17 -0.000218214 0.000949706" quat="0 1 0 0" mesh="wrist_roll_follower_so101_v1"/> -->
                <!-- <geom type="mesh" friction="15 15 15" class="collision" pos="8.32667e-17 -0.000218214 0.000949706" quat="0 1 0 0" mesh="wrist_roll_follower_so101_v1" material="wrist_roll_follower_so101_v1_material"/> -->
                
                <!-- Frame gripperframe -->
                <site group="3" name="gripperframe" pos="-0.0079 -0.000218121 -0.0981274" quat="0.707107 -0 0.707107 -2.37788e-17"/>
                <!-- Link moving_jaw_so101_v1 -->
                <body name="moving_jaw_so101_v1" pos="0.0202 0.0188 -0.0234" quat="0.707107 0.707107 -1.85362e-08 1.85362e-08">
                  <!-- Joint from gripper to moving_jaw_so101_v1 -->
                  <joint axis="0 0 1" name="gripper" type="hinge" range="-0.17453297762778586 1.7453291995659765" class="sts3215"/>
                  <inertial pos="-0.00157495 -0.0300244 0.0192755" mass="0.012" fullinertia="6.61427e-06 1.89032e-06 5.28738e-06 -3.19807e-07 -5.90717e-09 -1.09945e-07"/>
                  
                  <!-- 运动夹爪: Part moving_jaw_so101_v1 -->
                  <geom type="mesh" class="visual" pos="-5.55112e-17 -5.55112e-17 0.0189" quat="1 -0 3.00524e-16 -2.00834e-17" mesh="moving_jaw_so101_v1" material="arm_color"/>
          <!-- 这里 -->
                  <geom type="mesh" friction="1 0.005 0.0001" class="finger_collision" pos="-5.55112e-17 -5.55112e-17 0.0189" quat="1 -0 3.00524e-16 -2.00834e-17" mesh="moving_jaw_so101_v1"/>
          <!-- 手工肉垫 -->
                  <geom class="finger_collision" name="moving_jaw_pad_1" size="0.001 0.005 0.004" pos="-0.0113 -0.077 0.0185" rgba="0 0 1 0.5"/>
                  <geom class="finger_collision" name="moving_jaw_pad_2" size="0.001 0.005 0.006" pos="-0.0093 -0.067 0.0185" rgba="0 0 1 0.5"/>
                  <geom class="finger_collision" name="moving_jaw_pad_3" size="0.001 0.01 0.006" pos="-0.0073 -0.055 0.0185" rgba="0 0 1 0.5"/>
                  <geom class="finger_collision" name="moving_jaw_pad_4" size="0.001 0.01 0.008" pos="-0.0073 -0.035 0.0185" rgba="0 0 1 0.5"/>
                  
                  <!-- <geom name="gripper_right_collision" friction="1 0.005 0.0001" class="finger_collision" type="box" pos="-0.01 -0.03 0.019" size="0.005 0.05 0.01" condim="4" contype="1" conaffinity="1" rgba="0 1 0 0.8"/> -->
                  <!-- <geom type="mesh" class="collision" pos="-5.55112e-17 -5.55112e-17 0.0189" quat="1 -0 3.00524e-16 -2.00834e-17" mesh="moving_jaw_so101_v1" material="moving_jaw_so101_v1_material"/> -->
                </body>
              </body>
            </body>
          </body>
        </body>
      </body>
    </body>
  </worldbody>
  
  <asset>
  <!-- 从100借来的固定爪碰撞 -->
    <!-- <mesh name="From100_Fixed_Jaw_Collision" file="From100_Fixed_Jaw_Collision.stl"/> -->
    <mesh name="From100_Fixed_Jaw_Collision_1" file="From100_Fixed_Jaw_Collision_1.stl"/>
    <mesh name="From100_Fixed_Jaw_Collision_2" file="From100_Fixed_Jaw_Collision_2.stl"/>
  <!-- 101夹爪模型 -->
    <mesh file="wrist_roll_pitch_so101_v2.stl"/>
    <mesh file="moving_jaw_so101_v1.stl"/>

    <mesh file="waveshare_mounting_plate_so101_v2.stl"/>
    <mesh file="sts3215_03a_v1.stl"/>
    <mesh file="motor_holder_so101_base_v1.stl"/>
    <mesh file="wrist_roll_follower_so101_v1.stl"/>
    <mesh file="base_motor_holder_so101_v1.stl"/>
    <mesh file="upper_arm_so101_v1.stl"/>
    <mesh file="under_arm_so101_v1.stl"/>
    <mesh file="rotation_pitch_so101_v1.stl"/>
    <mesh file="motor_holder_so101_wrist_v1.stl"/>
    <mesh file="sts3215_03a_no_horn_v1.stl"/>
    <mesh file="base_so101_v2.stl"/>

    <!-- 统一的机械臂颜色 -->
    <!-- <material name="arm_color" rgba="1 0.82 0.12 1"/> -->
    <!-- <material name="arm_color" rgba="0.992 0.961 0.4 1"/> -->
    <material name="arm_color" rgba="0.9 0.9 0.9 1"/>
    
    <!-- 电机颜色（保持黑色） -->
    <material name="motor_color" rgba="0.1 0.1 0.1 1"/>
  </asset>
  <actuator>
    <position class="sts3215" name="shoulder_pan" joint="shoulder_pan" forcerange="-3.35 3.35" ctrlrange="-1.91986 1.91986"/>
    <position class="sts3215" name="shoulder_lift" joint="shoulder_lift" forcerange="-3.35 3.35" ctrlrange="-1.74533 1.74533"/>
    <position class="sts3215" name="elbow_flex" joint="elbow_flex" forcerange="-3.35 3.35" ctrlrange="-1.69 1.69"/>
    <position class="sts3215" name="wrist_flex" joint="wrist_flex" forcerange="-3.35 3.35" ctrlrange="-1.65806 1.65806"/>
    <position class="sts3215" name="wrist_roll" joint="wrist_roll" forcerange="-3.35 3.35" ctrlrange="-2.74385 2.84121"/>
    <position class="sts3215" name="gripper" joint="gripper" forcerange="-3.35 3.35" ctrlrange="-0.17453 1.74533"/>
  </actuator>
  <equality/>
</mujoco>
